2022-04-23 18:49:39,439 INFO    MainThread:86470 [internal.py:wandb_internal():90] W&B internal server running at pid: 86470, started at: 2022-04-23 18:49:39.439633
2022-04-23 18:49:39,442 DEBUG   SenderThread:86470 [sender.py:send():232] send: header
2022-04-23 18:49:39,442 INFO    WriterThread:86470 [datastore.py:open_for_write():75] open: /home/tooba/Documents/codes/Training-Vision-Transformers-Using-PyTorch-Lightning/wandb/run-20220423_184938-ebc8hif1/run-ebc8hif1.wandb
2022-04-23 18:49:39,442 DEBUG   SenderThread:86470 [sender.py:send():232] send: run
2022-04-23 18:49:39,443 INFO    SenderThread:86470 [sender.py:_maybe_setup_resume():489] checking resume status for None/ViT_experiments/ebc8hif1
2022-04-23 18:49:41,309 ERROR   SenderThread:86470 [internal_api.py:execute():143] 403 response executing GraphQL.
2022-04-23 18:49:41,310 ERROR   SenderThread:86470 [internal_api.py:execute():144] 
<html><head>
<meta http-equiv="content-type" content="text/html;charset=utf-8">
<title>403 Forbidden</title>
</head>
<body text=#000000 bgcolor=#ffffff>
<h1>Error: Forbidden</h1>
<h2>Your client does not have permission to get URL <code>/graphql</code> from this server.</h2>
<h2></h2>
</body></html>

2022-04-23 18:49:41,443 INFO    WriterThread:86470 [datastore.py:close():279] close: /home/tooba/Documents/codes/Training-Vision-Transformers-Using-PyTorch-Lightning/wandb/run-20220423_184938-ebc8hif1/run-ebc8hif1.wandb
2022-04-23 18:49:41,444 INFO    HandlerThread:86470 [handler.py:finish():806] shutting down handler
2022-04-23 18:49:41,444 ERROR   MainThread:86470 [internal.py:wandb_internal():165] Thread SenderThread:
Traceback (most recent call last):
  File "/home/tooba/.local/lib/python3.8/site-packages/wandb/sdk/lib/retry.py", line 102, in __call__
    result = self._call_fn(*args, **kwargs)
  File "/home/tooba/.local/lib/python3.8/site-packages/wandb/sdk/internal/internal_api.py", line 140, in execute
    return self.client.execute(*args, **kwargs)
  File "/home/tooba/.local/lib/python3.8/site-packages/wandb/vendor/gql-0.2.0/wandb_gql/client.py", line 52, in execute
    result = self._get_result(document, *args, **kwargs)
  File "/home/tooba/.local/lib/python3.8/site-packages/wandb/vendor/gql-0.2.0/wandb_gql/client.py", line 60, in _get_result
    return self.transport.execute(document, *args, **kwargs)
  File "/home/tooba/.local/lib/python3.8/site-packages/wandb/vendor/gql-0.2.0/wandb_gql/transport/requests.py", line 39, in execute
    request.raise_for_status()
  File "/usr/lib/python3/dist-packages/requests/models.py", line 940, in raise_for_status
    raise HTTPError(http_error_msg, response=self)
requests.exceptions.HTTPError: 403 Client Error: Forbidden for url: https://api.wandb.ai/graphql

During handling of the above exception, another exception occurred:

Traceback (most recent call last):
  File "/home/tooba/.local/lib/python3.8/site-packages/wandb/apis/normalize.py", line 22, in wrapper
    return func(*args, **kwargs)
  File "/home/tooba/.local/lib/python3.8/site-packages/wandb/sdk/internal/internal_api.py", line 801, in run_resume_status
    response = self.gql(
  File "/home/tooba/.local/lib/python3.8/site-packages/wandb/sdk/lib/retry.py", line 118, in __call__
    if not check_retry_fn(e):
  File "/home/tooba/.local/lib/python3.8/site-packages/wandb/util.py", line 879, in no_retry_auth
    raise CommError("Permission denied, ask the project owner to grant you access")
wandb.errors.CommError: Permission denied, ask the project owner to grant you access

During handling of the above exception, another exception occurred:

Traceback (most recent call last):
  File "/home/tooba/.local/lib/python3.8/site-packages/wandb/sdk/internal/internal_util.py", line 51, in run
    self._run()
  File "/home/tooba/.local/lib/python3.8/site-packages/wandb/sdk/internal/internal_util.py", line 102, in _run
    self._process(record)
  File "/home/tooba/.local/lib/python3.8/site-packages/wandb/sdk/internal/internal.py", line 310, in _process
    self._sm.send(record)
  File "/home/tooba/.local/lib/python3.8/site-packages/wandb/sdk/internal/sender.py", line 234, in send
    send_handler(record)
  File "/home/tooba/.local/lib/python3.8/site-packages/wandb/sdk/internal/sender.py", line 662, in send_run
    error = self._maybe_setup_resume(run)
  File "/home/tooba/.local/lib/python3.8/site-packages/wandb/sdk/internal/sender.py", line 492, in _maybe_setup_resume
    resume_status = self._api.run_resume_status(
  File "/home/tooba/.local/lib/python3.8/site-packages/wandb/apis/normalize.py", line 58, in wrapper
    raise CommError(message, err).with_traceback(sys.exc_info()[2])
  File "/home/tooba/.local/lib/python3.8/site-packages/wandb/apis/normalize.py", line 22, in wrapper
    return func(*args, **kwargs)
  File "/home/tooba/.local/lib/python3.8/site-packages/wandb/sdk/internal/internal_api.py", line 801, in run_resume_status
    response = self.gql(
  File "/home/tooba/.local/lib/python3.8/site-packages/wandb/sdk/lib/retry.py", line 118, in __call__
    if not check_retry_fn(e):
  File "/home/tooba/.local/lib/python3.8/site-packages/wandb/util.py", line 879, in no_retry_auth
    raise CommError("Permission denied, ask the project owner to grant you access")
wandb.errors.CommError: Permission denied, ask the project owner to grant you access
2022-04-23 18:49:43,466 INFO    MainThread:86470 [internal.py:handle_exit():80] Internal process exited
